Workbook

Sheet بيانات الإصدار والاعتماد
B4: معلومات الوثيقة والاعتماد وضبط الجودة
B6: التصنيف الأمني | C6: سري للاستخدام الداخلي (Confidential - Internal Banking Use)
B7: عنوان الوثيقة | C7: بيان التطبيق للضوابط الأمنية — بنك الآفاق الرقمية (Statement of Applicability)
B8: المرجع الإجرائي | C8: ISMS-FORM-06-2
B9: رقم الإصدار | C9: 1
B10: تاريخ الاعتماد | C10: 11 سبتمبر 2026 م
B11: الاعتماد والمصادقة | C11: د. نورة القحطاني (الرئيس التنفيذي) وأ. عبدالله المحيسن (رئيس مجلس الإدارة)
B12: مالك الوثيقة | C12: أ. سارة الحربي — مدير أمن المعلومات (CISO)
B13: فريق الإعداد والاستشارة | C13: محمد العامري (قائد المشروع)، محمد الكشري، محمد شماخ، محمد الأصبحي
B14: المرجع المعياري | C14: ISO/IEC 27001:2022 Clause 6.1.3 (d) & Annex A (93 Controls)
B15: الامتثال التنظيمي | C15: إطار الأمن السيبراني للبنك المركزي السعودي (ساما) ونظام حماية البيانات الشخصية (سدايا)

Sheet بيان التطبيق (SoA)
B5: نظم إدارة أمن المعلومات: المتطلبات
B8: القسم / المجال | C8: الضابط الأمني المرجعي | D8: هل الضابط خاضع للتطبيق؟ | E8: حالة التطبيق الفعلي? | F8: مبررات الشمول أو الاستبعاد | G8: الملاحظات، الأدلة التشغيلية، ومواءمتها مع بنك الآفاق
B10: A.5 الضوابط التنظيمية | C10: A.5.1 سياسات أمن المعلومات | D10: نعم | E10: نعم | F10: مطلب إلزامي في المواصفة وإطار ساما للأمن السيبراني لتوفير التوجيه الإداري. | G10: تم اعتماد ونشر السياسة العامة المظلية لأمن المعلومات (ISMS-DOC-05-4) و39 سياسة تخصصية فرعية بموافقة الرئيس التنفيذي ومجلس الإدارة.
C11: A.5.2 أدوار ومسؤوليات أمن المعلومات | D11: نعم | E11: نعم | F11: إلزامية تحديد المسؤوليات والمساءلة وتفادي تضارب الصلاحيات. | G11: تحديد هيكل واضح: CISO (أ. سارة الحربي) مستقلة عن IT (م. فهد العتيبي)، وتوزيع مهام الـ SOC، الاستجابة للحوادث، والحوكمة وتقييم المخاطر.
C12: A.5.3 الفصل بين الواجبات | D12: نعم | E12: نعم | F12: منع إساءة استخدام الصلاحيات، والحد من الأخطاء والاحتيال المالي الداخلي. | G12: فصل بيئات التطوير عن الإنتاج، فصل صلاحيات مديري قواعد البيانات عن العمليات المالية، وفرض اعتماد ثنائي للمدفوعات.
C13: A.5.4 مسؤوليات الإدارة | D13: نعم | E13: نعم | F13: إلزام القيادات بإنفاذ تعليمات الأمن السيبراني في كافة القطاعات. | G13: تضمين الالتزام الأمني في اتفاقيات الأداء السنوية لمديري الإدارات (KPIs)، والمشاركة الإلزامية في اجتماعات مراجعة الإدارة الدورية.
C14: A.5.5 الاتصال بالسلطات والجهات التنظيمية | D14: نعم | E14: نعم | F14: الامتثال للمتطلبات التنظيمية للبنك المركزي السعودي (ساما) والجهات الأمنية. | G14: تحديد قنوات اتصال رسمية مع ساما، سدايا، ومكافحة الجرائم المعلوماتية؛ وإلزامية الإبلاغ الفوري عن الحوادث السيبرانية الجسيمة خلال ساعتين.
C15: A.5.6 الاتصال بمجموعات الاهتمام المهنية | D15: نعم | E15: نعم | F15: متابعة مستجدات التهديدات السيبرانية وأفضل الممارسات المصرفية. | G15: الاشتراك في لجان الأمن السيبراني التابعة لساما، والمجلس المالي لمشاركة معلومات التهديدات (FS-ISAC) والمراكز الوطنية.
C16: A.5.7 معلومات التهديدات السيبرانية (Threat Intelligence) | D16: نعم | E16: نعم | F16: مطلب حيوي لمواجهة عصابات الجرائم المنظمة وهجمات الفدية المستهدفة للبنوك. | G16: تفعيل تغذية مؤشرات الاختراق (IoCs) وتكاملها مع جدران الحماية Palo Alto وحلول FortiWeb WAF، وتكليف فريق تقييم المخاطر بتحليلها.
C17: A.5.8 أمن المعلومات في إدارة المشاريع | D17: نعم | E17: نعم | F17: ضمان إدراج متطلبات الأمن السيبراني في كافة المشروعات التقنية والتطويرية. | G17: تطبيق مبدأ 'الأمان بالتصميم' في إدارة المشاريع ومراجعة أمان مشروع تطبيق 'آفاق بلس' ومشروع استبدال نظام الرواتب القديم.
C18: A.5.9 جرد الأصول والمعلومات المرتبطة بها | D18: نعم | E18: نعم | F18: تحديد وحماية كافة الأصول المادية والمعلوماتية والبرمجية التابعة للبنك. | G18: توثيق سجل جرد الأصول الشامل (Asset Register) الحاوي لـ 16 فئة أصول رئيسية مع تعيين مالك رسمي وتحديد الحرجية (CIA) لكل أصل.
C19: A.5.10 الاستخدام المقبول للمعلومات والأصول | D19: نعم | E19: نعم | F19: سد الفجوة التنظيمية ومنع استخدام مقدرات البنك لأغراض غير مصرح بها. | G19: تحديث سياسة الاستخدام المقبول (AUP)، حظر استخدام البريد البنكي لأغراض شخصية، تقييد التصفح، وتوقيع إقرار سنوي ملزم من كافة الموظفين.
C20: A.5.11 إعادة الأصول وممتلكات البنك | D20: نعم | E20: نعم | F20: منع تسريب بيانات البنك أو فقدان الأجهزة عند انتهاء الخدمة أو تغيير العمل. | G20: إجراءات إخلاء طرف مشددة تشمل استعادة الحواسيب المحمولة (HP)، الهواتف، والبطاقات الذكية فور استقالة أو إنهاء عقد أي موظف.
C21: A.5.12 تصنيف المعلومات والبيانات | D21: نعم | E21: نعم | F21: ضمان منح الحماية المناسبة لكل مستوى من البيانات المصرفية والعملاء. | G21: اعتماد نظام تصنيف رباعي: (سري للغاية، سري، داخلي، عام) وإلزامية تصنيف قواعد بيانات العملاء والمعاملات كـ 'سري للغاية'.
C22: A.5.13 وسم وتسمية المعلومات (Data Labelling) | D22: نعم | E22: نعم | F22: تسهيل التعرف على حساسية المستندات وضمان التعامل الآمن معها. | G22: تفعيل الوسم الآلي للوثائق في Office 365 / SharePoint، وإلزام الموظفين بوضع علامة مائية للمستندات السرية وسجلات الرواتب.
... C46: A.5.37 توثيق إجراءات التشغيل (SOPs) | D46: نعم | E46: نعم | F46: توحيد العمليات التشغيلية وتفادي الأخطاء البشرية الفردية لمهندسي التقنية. | G46: إصدار وتوثيق 4 أدلة تشغيلية قياسية: النسخ الاحتياطي، إدارة التشفير، إدارة التحديثات والترقيع، وإدارة الثغرات، ومراجعتها سنوياً.
C47: المجموع (Totals): | D47: =COUNTIF(D10:D46,"نعم")+COUNTIF(D10:D46,"Yes") -> 37 | E47: =COUNTIF(E10:E46,"نعم")+COUNTIF(E10:E46,"Yes") -> 37
B49: A.6 ضوابط الأفراد
C50: A.6.1 الفحص الأمني للموظفين (Screening) | D50: نعم | E50: نعم | F50: التحقق من نزاهة وأهلية الموظفين قبل تعيينهم في بيئة مصرفية حساسة. | G50: إجراء مسح أمني شامل وفحص السجلات الجنائية والتحقق من المؤهلات والخبرات السابقة لكافة المرشحين بالتعاون مع الموارد البشرية.
C51: A.6.2 شروط وأحكام التوظيف | D51: نعم | E51: نعم | F51: إلزام الموظفين تعاقدياً بمسؤولياتهم تجاه أمن المعلومات وسياسات البنك. | G51: تضمين شروط أمن المعلومات واتفاقيات السرية والتبعات القانونية للمخالفات في صلب عقود العمل لجميع الموظفين والمتعاقدين.
C52: A.6.3 التوعية والتدريب والتعليم في أمن المعلومات | D52: نعم | E52: نعم | F52: معالجة نتائج محاكاة التصيد السابقة (نقوع 25% من الموظفين ونقر 40% بالتسويق). | G52: إطلاق حملات توعوية شهرية متعددة اللغات، محاكاة دورية للتصيد المالي، وتدريب متخصص لموظفي المالية والتسويق لخفض النقر لأقل من 3%.
C53: A.6.4 الإجراءات التأديبية والمساءلة | D53: نعم | E53: نعم | F53: الردع والمساءلة الإدارية عن أي إهمال أو انتهاك متعمد للسياسات الأمنية. | G53: اعتماد لائحة جزاءات واضحة ومتدرجة (إنذار، خصم، فصل، ملاحقة قضائية) تطبق بشفافية بالتعاون مع الموارد البشرية والشؤون القانونية.
C54: A.6.5 المسؤوليات بعد إنهاء الخدمة أو تغيير العمل | D54: نعم | E54: نعم | F54: السيطرة على المخاطر الناجمة عن دوران الموظفين بنسبة 12% في IT. | G54: توقيع إقرار استمرار الالتزام بالسرية المصرفية بعد الاستقالة، والتعطيل الفوري والشامل لكافة الحسابات والصلاحيات في نفس يوم العمل الأخير.
C55: A.6.6 اتفاقيات السرية وعدم الإفصاح (NDA) | D55: نعم | E55: نعم | F55: حماية أسرار البنك، بيانات العملاء، والكود المصدري من النشر غير المصرح. | G55: توقيع اتفاقيات عدم إفصاح ملزمة وقابلة للإنفاذ القانوني مع كافة الموظفين، المطورين، والاستشاريين والشركات الخارجية.
C56: A.6.7 العمل عن بُعد (Remote Working) | D56: نعم | E56: نعم | F56: تأمين الوصول عن بعد للموظفين المتنقلين والإدارات المصرح لها. | G56: فرض الاتصال عبر شبكة افتراضية خاصة مشفرة (Cisco AnyConnect VPN)، مصادقة ثنائية (RSA SecurID)، وتطبيق تشفير الأقراص على أجهزة العمل.
C57: A.6.8 الإبلاغ عن الأحداث والشبهات الأمنية | D57: نعم | E57: نعم | F57: رفع معدل إبلاغ الموظفين عن التهديدات من 8% إلى أكثر من 75%. | G57: إضافة زر إبلاغ مباشر (Report Phishing) في Outlook، توفير خط ساخن مع الـ SOC، وإقرار سياسة عدم معاقبة المبلّغين بحسن نية.
C58: المجموع (Totals): | D58: =COUNTIF(D50:D57,"نعم")+COUNTIF(D50:D57,"Yes") -> 8 | E58: =COUNTIF(E50:E57,"نعم")+COUNTIF(E50:E57,"Yes") -> 8
B60: A.7 الضوابط المادية
C61: A.7.1 المحيط الأمني الفيزيائي (Physical Perimeters) | D61: نعم | E61: نعم | F61: حماية المباني والمراكز الحساسة من الدخول والتسلل الفيزيائي غير المصرح. | G61: حواجز أمنية وبوابات تفتيش بالمقر الرئيسي (الرياض)، أسوار أمنية لمركز التعافي بجدة، وتأمين محيط الفروع وأماكن الصرافات.
C62: A.7.2 التحكم في الدخول الفيزيائي | D62: نعم | E62: نعم | F62: قصر الدخول لمراكز البيانات والمناطق الحساسة على المخولين حصراً. | G62: نظام مصادقة بيومترية (بصمة إصبع) وبطاقات ذكية للدخول لمركز البيانات (الطابق 3) وغرف الخوادم بالفروع مع حفظ سجلات الدخول آلياً.
C63: A.7.3 تأمين المكاتب والغرف والمرافق | D63: نعم | E63: نعم | F63: منع الوصول غير المصرح إلى المكاتب التنفيذية وغرف العمليات المصرفية. | G63: أقفال إلكترونية، مناطق استقبال معزولة للزوار، وتحديد مستويات وصول فيزيائية منفصلة لكل طابق في مبنى الإدارة العامة.
C64: A.7.4 المراقبة الأمنية الفيزيائية (CCTV) | D64: نعم | E64: نعم | F64: الرصد اللحظي للأحداث الفيزيائية والتحقيق في الحوادث الأمنية. | G64: تغطية شاملة بنظام كاميرات مراقبة رقمية عالية الدقة (CCTV) على مدار الساعة لكافة المداخل والممرات ومركز البيانات والصرافات الآلية.
C65: A.7.5 الحماية من التهديدات المادية والبيئية | D65: نعم | E65: نعم | F65: حماية البنية التحتية من الحرائق، الفيضانات، وتغيرات درجات الحرارة والرطوبة. | G65: أنظمة إطفاء غازي تلقائي (FM200)، أجهزة استشعار تسرب المياه، وأنظمة تكييف دقيق (Precision Cooling) في مراكز البيانات.
C66: A.7.6 العمل في المناطق الآمنة | D66: نعم | E66: نعم | F66: منع تصوير أو تسريب المعلومات الحساسة من داخل غرف الخوادم والـ SOC. | G66: حظر اصطحاب الهواتف الشخصية وكاميرات التصوير داخل مركز العمليات الأمنية (الطابق 4) وغرفة خوادم مركز البيانات، وتوثيق سجل المرافقين.
C67: A.7.7 سياسة المكتب النظيف والشاشة النقية | D67: نعم | E67: نعم | F67: منع الاطلاع غير المصرح على الشاشات والمستندات المصرفية المتروكة. | G67: قفل شاشات الحاسوب آلياً بعد 3 دقائق خمول، إلزامية إخلاء المكاتب من الشيكات وكشوفات الحسابات، وتوفير آلات تمزيق مستندات متطورة.
C68: A.7.8 وضع وحماية المعدات والأجهزة | D68: نعم | E68: نعم | F68: حماية الخوادم وأجهزة الشبكة من التلف الفيزيائي والوصول غير المصرح. | G68: تثبيت الخوادم وأجهزة Cisco ASR في كبائن شبكية مقفلة داخل غرف مكيفة ومؤمنة ميكانيكياً في المقر والفروع.
C69: A.7.9 أمن الأصول خارج مقار البنك | D69: نعم | E69: نعم | F69: تلافي تكرار حادثة فقدان لابتوب مدير التسويق أثناء السفر خارج المملكة. | G69: فرض التشفير الكامل للأقراص، تقييد صلاحيات نسخ البيانات على وسائط خارجية، وإلزام الموظفين بحفظ الأجهزة في أماكن آمنة أثناء السفر.
C70: A.7.10 وسائط التخزين (Storage Media) | D70: نعم | E70: نعم | F70: منع سرقة وسائط التخزين أو تسريب البيانات المخزنة عليها. | G70: حفظ أشرطة النسخ الاحتياطي في خزائن مضادة للحريق، تشفير وسائط التخزين، وحظر منافذ USB على حواسيب الموظفين عبر برامج الحماية.
C71: A.7.11 المرافق الداعمة والخدمات الأساسية | D71: نعم | E71: نعم | F71: ضمان استمرار إمدادات الطاقة وتفادي انقطاع الأنظمة المصرفية. | G71: توفير وحدات طاقة غير منقطعة (UPS) مزدوجة ومولدات كهرباء ديزل احتياطية تعمل تلقائياً في المقر، مركز جدة، وكافة الفروع.
C72: A.7.12 أمن كابلات الشبكة والطاقة | D72: نعم | E72: نعم | F72: حماية كابلات نقل البيانات من التنصت، التلف الميكانيكي، أو القطع. | G72: تمديد كابلات الشبكة في مسارات وأنابيب معدنية محمية (Conduits) تحت الأرضيات المرفوعة، مع الفصل التام بين مسارات الطاقة والبيانات.
...

Sheet لوحة المؤشرات
B1: لوحة مؤشرات وملخص بيان التطبيق — بنك الآفاق الرقمية (SoA Dashboard)
B4: نتائج ومؤشرات الامتثال لبيان التطبيق (Statement of Applicability Results)
B6: مجال الضوابط في المواصفة AREA OF STANDARD | C6: إجمالي عدد الضوابط NO OF CONTROLS | D6: الضوابط الخاضعة للتطبيق APPLICABLE CONTROLS | E6: نسبة الانطباق % CONTROLS APPLICABLE | F6: الضوابط المطبقة فعلياً CONTROLS IMPLEMENTED | G6: نسبة التطبيق الفعلي % APP CONTROLS IMPLEMENTED
B7: A.5 الضوابط التنظيمية (Organizational controls) | C7: 37 | D7: ='بيان التطبيق (SoA)'!D47 -> 37 | E7: =D7/C7 -> 1 | F7: ='بيان التطبيق (SoA)'!E47 -> 37 | G7: =F7/D7 -> 1
B8: A.6 ضوابط الأفراد (People controls) | C8: 8 | D8: ='بيان التطبيق (SoA)'!D58 -> 8 | E8: =D8/C8 -> 1 | F8: ='بيان التطبيق (SoA)'!E58 -> 8 | G8: =F8/D8 -> 1
B9: A.7 الضوابط المادية (Physical controls) | C9: 14 | D9: ='بيان التطبيق (SoA)'!D75 -> 14 | E9: =D9/C9 -> 1 | F9: ='بيان التطبيق (SoA)'!E75 -> 14 | G9: =F9/D9 -> 1
B10: A.8 الضوابط التقنية (Technological controls) | C10: 34 | D10: ='بيان التطبيق (SoA)'!D112 -> 34 | E10: =D10/C10 -> 1 | F10: ='بيان التطبيق (SoA)'!E112 -> 34 | G10: =F10/D10 -> 1
B11: الإجمالي العام (Total) | C11: =SUM(C7:C10) -> 93 | D11: =SUM(D7:D10) -> 93 | E11: =D11/C11 -> 1 | F11: =SUM(F7:F10) -> 93 | G11: =F11/D11 -> 1
B16: عدد الضوابط المنطبقة والمطبقة حسب المجال (Number of Controls)
B18: مجال الضوابط في المواصفة | C18: الضوابط المنطبقة | D18: الضوابط المطبقة
B19: A.8 الضوابط التقنية | C19: =D10 -> 34 | D19: =F10 -> 34
B20: A.7 الضوابط المادية | C20: =D9 -> 14 | D20: =F9 -> 14
B21: A.6 ضوابط الأفراد | C21: =D8 -> 8 | D21: =F8 -> 8
B22: A.5 الضوابط التنظيمية | C22: =D7 -> 37 | D22: =F7 -> 37
B24: نسب الانطباق والتطبيق الفعلي للضوابط (Percentage of Controls)
B26: مجال الضوابط في المواصفة | C26: نسبة التطبيق الفعلي | D26: نسبة الانطباق
B27: A.5 الضوابط التنظيمية | C27: =G7 -> 1 | D27: =E7 -> 1
B28: A.6 ضوابط الأفراد | C28: =G8 -> 1 | D28: =E8 -> 1
B29: A.7 الضوابط المادية | C29: =G9 -> 1 | D29: =E9 -> 1
B30: A.8 الضوابط التقنية | C30: =G10 -> 1 | D30: =E10 -> 1
B32: بيانات مخطط الرادار لنسب التطبيق الفعلي (Radar Chart Data)
B34: مجال الضوابط في المواصفة | C34: نسبة التطبيق الفعلي | D34: نسبة الانطباق
B35: A.5 الضوابط التنظيمية | C35: =G7 -> 1 | D35: =E7 -> 1
B36: A.6 ضوابط الأفراد | C36: =G8 -> 1 | D36: =E8 -> 1
B37: A.7 الضوابط المادية | C37: =G9 -> 1 | D37: =E9 -> 1
B38: A.8 الضوابط التقنية | C38: =G10 -> 1 | D38: =E10 -> 1
